<?xml version="1.0" encoding="UTF-8"?>
<!-- Generated by org.testng.reporters.JUnitReportReporter -->
<testsuite hostname="DESKTOP-1T5BJDV" failures="1" tests="5" name="authentication.Login" time="4.258" errors="1" timestamp="2024-07-09T19:47:50 IST" skipped="0">
  <testcase classname="authentication.Login" name="tc_05PomTest" time="1.313"/>
  <testcase classname="authentication.Login" name="tC_02test_Failed" time="0.133">
    <failure message="java.lang.AssertionError" type="java.lang.AssertionError">
      <![CDATA[java.lang.AssertionError: java.lang.AssertionError
at baseClases.Helper.triggerAssertFail(Helper.java:112)
at authentication.Login.tC_02test_Failed(Login.java:60)
at java.base/jdk.internal.reflect.DirectMethodHandleAccessor.invoke(DirectMethodHandleAccessor.java:103)
at java.base/java.lang.reflect.Method.invoke(Method.java:580)
at org.testng.internal.invokers.MethodInvocationHelper.invokeMethod(MethodInvocationHelper.java:141)
at org.testng.internal.invokers.TestInvoker.invokeMethod(TestInvoker.java:686)
at org.testng.internal.invokers.TestInvoker.invokeTestMethod(TestInvoker.java:230)
at org.testng.internal.invokers.MethodRunner.runInSequence(MethodRunner.java:63)
at org.testng.internal.invokers.TestInvoker$MethodInvocationAgent.invoke(TestInvoker.java:992)
at org.testng.internal.invokers.TestInvoker.invokeTestMethods(TestInvoker.java:203)
at org.testng.internal.invokers.TestMethodWorker.invokeTestMethods(TestMethodWorker.java:154)
at org.testng.internal.invokers.TestMethodWorker.run(TestMethodWorker.java:134)
at java.base/java.util.ArrayList.forEach(ArrayList.java:1596)
at org.testng.TestRunner.privateRun(TestRunner.java:739)
at org.testng.TestRunner.run(TestRunner.java:614)
at org.testng.SuiteRunner.runTest(SuiteRunner.java:421)
at org.testng.SuiteRunner.runSequentially(SuiteRunner.java:413)
at org.testng.SuiteRunner.privateRun(SuiteRunner.java:373)
at org.testng.SuiteRunner.run(SuiteRunner.java:312)
at org.testng.SuiteRunnerWorker.runSuite(SuiteRunnerWorker.java:52)
at org.testng.SuiteRunnerWorker.run(SuiteRunnerWorker.java:95)
at org.testng.TestNG.runSuitesSequentially(TestNG.java:1274)
at org.testng.TestNG.runSuitesLocally(TestNG.java:1208)
at org.testng.TestNG.runSuites(TestNG.java:1112)
at org.testng.TestNG.run(TestNG.java:1079)
at org.testng.remote.AbstractRemoteTestNG.run(AbstractRemoteTestNG.java:115)
at org.testng.remote.RemoteTestNG.initAndRun(RemoteTestNG.java:293)
at org.testng.remote.RemoteTestNG.main(RemoteTestNG.java:91)
Caused by: java.lang.AssertionError
at authentication.Login.tC_02test_Failed(Login.java:55)
... 26 more
]]>
    </failure>
  </testcase> <!-- tC_02test_Failed -->
  <testcase classname="authentication.Login" name="tC_03test_Failed1" time="0.304">
    <error message="java.lang.Exception" type="java.lang.Exception">
      <![CDATA[java.lang.Exception: java.lang.Exception
at baseClases.Helper.triggerExceptionFail(Helper.java:131)
at authentication.Login.tC_03test_Failed1(Login.java:72)
at java.base/jdk.internal.reflect.DirectMethodHandleAccessor.invoke(DirectMethodHandleAccessor.java:103)
at java.base/java.lang.reflect.Method.invoke(Method.java:580)
at org.testng.internal.invokers.MethodInvocationHelper.invokeMethod(MethodInvocationHelper.java:141)
at org.testng.internal.invokers.TestInvoker.invokeMethod(TestInvoker.java:686)
at org.testng.internal.invokers.TestInvoker.invokeTestMethod(TestInvoker.java:230)
at org.testng.internal.invokers.MethodRunner.runInSequence(MethodRunner.java:63)
at org.testng.internal.invokers.TestInvoker$MethodInvocationAgent.invoke(TestInvoker.java:992)
at org.testng.internal.invokers.TestInvoker.invokeTestMethods(TestInvoker.java:203)
at org.testng.internal.invokers.TestMethodWorker.invokeTestMethods(TestMethodWorker.java:154)
at org.testng.internal.invokers.TestMethodWorker.run(TestMethodWorker.java:134)
at java.base/java.util.ArrayList.forEach(ArrayList.java:1596)
at org.testng.TestRunner.privateRun(TestRunner.java:739)
at org.testng.TestRunner.run(TestRunner.java:614)
at org.testng.SuiteRunner.runTest(SuiteRunner.java:421)
at org.testng.SuiteRunner.runSequentially(SuiteRunner.java:413)
at org.testng.SuiteRunner.privateRun(SuiteRunner.java:373)
at org.testng.SuiteRunner.run(SuiteRunner.java:312)
at org.testng.SuiteRunnerWorker.runSuite(SuiteRunnerWorker.java:52)
at org.testng.SuiteRunnerWorker.run(SuiteRunnerWorker.java:95)
at org.testng.TestNG.runSuitesSequentially(TestNG.java:1274)
at org.testng.TestNG.runSuitesLocally(TestNG.java:1208)
at org.testng.TestNG.runSuites(TestNG.java:1112)
at org.testng.TestNG.run(TestNG.java:1079)
at org.testng.remote.AbstractRemoteTestNG.run(AbstractRemoteTestNG.java:115)
at org.testng.remote.RemoteTestNG.initAndRun(RemoteTestNG.java:293)
at org.testng.remote.RemoteTestNG.main(RemoteTestNG.java:91)
Caused by: java.lang.Exception
at authentication.Login.tC_03test_Failed1(Login.java:70)
... 26 more
]]>
    </error>
  </testcase> <!-- tC_03test_Failed1 -->
  <testcase classname="authentication.Login" name="tC_04test_Skip" time="0.003"/>
  <testcase classname="authentication.Login" name="tC_01test_passed" time="2.505"/>
</testsuite> <!-- authentication.Login -->
